[33mWARNING [0m urllib3.connectionpool:connectionpool.py:868 Retrying (Retry(total=2, connect=None, read=None, redirect=None, status=None)) after connection broken by 'NameResolutionError("<urllib3.connection.HTTPSConnection object at 0x0000028F02113B80>: Failed to resolve 'none' ([Errno 11001] getaddrinfo failed)")': /wd/hub/session
[33mWARNING [0m urllib3.connectionpool:connectionpool.py:868 Retrying (Retry(total=1, connect=None, read=None, redirect=None, status=None)) after connection broken by 'NameResolutionError("<urllib3.connection.HTTPSConnection object at 0x0000028F02113FA0>: Failed to resolve 'none' ([Errno 11001] getaddrinfo failed)")': /wd/hub/session
[33mWARNING [0m urllib3.connectionpool:connectionpool.py:868 Retrying (Retry(total=0, connect=None, read=None, redirect=None, status=None)) after connection broken by 'NameResolutionError("<urllib3.connection.HTTPSConnection object at 0x0000028F021786D0>: Failed to resolve 'none' ([Errno 11001] getaddrinfo failed)")': /wd/hub/session