WARNING  urllib3.connectionpool:connectionpool.py:868 Retrying (Retry(total=2, connect=None, read=None, redirect=None, status=None)) after connection broken by 'NameResolutionError("<urllib3.connection.HTTPSConnection object at 0x00000250C1048F10>: Failed to resolve 'none' ([Errno 11001] getaddrinfo failed)")': /wd/hub/session
WARNING  urllib3.connectionpool:connectionpool.py:868 Retrying (Retry(total=1, connect=None, read=None, redirect=None, status=None)) after connection broken by 'NameResolutionError("<urllib3.connection.HTTPSConnection object at 0x00000250C104B790>: Failed to resolve 'none' ([Errno 11001] getaddrinfo failed)")': /wd/hub/session
WARNING  urllib3.connectionpool:connectionpool.py:868 Retrying (Retry(total=0, connect=None, read=None, redirect=None, status=None)) after connection broken by 'NameResolutionError("<urllib3.connection.HTTPSConnection object at 0x00000250C104B5E0>: Failed to resolve 'none' ([Errno 11001] getaddrinfo failed)")': /wd/hub/session