WARNING  urllib3.connectionpool:connectionpool.py:868 Retrying (Retry(total=2, connect=None, read=None, redirect=None, status=None)) after connection broken by 'NameResolutionError("<urllib3.connection.HTTPSConnection object at 0x000002C2FCD44DF0>: Failed to resolve 'none' ([Errno 11001] getaddrinfo failed)")': /wd/hub/session
WARNING  urllib3.connectionpool:connectionpool.py:868 Retrying (Retry(total=1, connect=None, read=None, redirect=None, status=None)) after connection broken by 'NameResolutionError("<urllib3.connection.HTTPSConnection object at 0x000002C2FCD479D0>: Failed to resolve 'none' ([Errno 11001] getaddrinfo failed)")': /wd/hub/session
WARNING  urllib3.connectionpool:connectionpool.py:868 Retrying (Retry(total=0, connect=None, read=None, redirect=None, status=None)) after connection broken by 'NameResolutionError("<urllib3.connection.HTTPSConnection object at 0x000002C2FCD47820>: Failed to resolve 'none' ([Errno 11001] getaddrinfo failed)")': /wd/hub/session